Workbook
Name AP_INSTALL_DAYS: Rates!$B$47
Name SWITCH_INSTALL_DAYS: Rates!$B$48
Name MOBILISATION_DAYS_PER_SITE: Rates!$B$49
Name DESIGN_DAYS_FIXED: Rates!$B$50
Name DESIGN_DAYS_PER_SITE: Rates!$B$51
Name PM_OVERHEAD_PCT: Rates!$B$52
Name OOH_UPLIFT: Rates!$B$53
Name AP_INCIDENT_RATE_PA: Rates!$B$54
Name SWITCH_INCIDENT_RATE_PA: Rates!$B$55
Name HOURS_PER_INCIDENT: Rates!$B$56
Name PRODUCTIVE_HOURS_PA: Rates!$B$57
Name WORKING_DAYS_PA: Rates!$B$58
Name APS_PER_NOC_FTE: Rates!$B$59
Name SD_CONTACTS_PER_USER_PA: Rates!$B$60
Name SD_MINUTES_PER_CONTACT: Rates!$B$61
Name PORTS_PER_SWITCH: Rates!$B$62
Name USERS_PER_PORT: Rates!$B$63
Name AP_UNIT_COST: Rates!$B$64
Name SWITCH_UNIT_COST: Rates!$B$65
Name TOOLING_PER_SITE: Rates!$B$66
Name OVERHEAD_PCT: Rates!$B$67
Name SITES_PER_POST: Rates!$B$68

Sheet Output
A1: SOLUTION & COST SUMMARY
A2: =Input!$B$6 | B2: =Input!$B$7
A3: ILLUSTRATIVE MODEL — synthetic rates, not NSC pricing.
A5: SOLUTION SHAPE
A6: Total sites | B6: =Input!$B$16
A7: Access points | B7: =Model!$B$4
A8: Access switches | B8: =Model!$B$6
A9: End users | B9: =Model!$B$5
A10: SLA tier / response | B10: =Input!$B$33&" — "&Model!$B$12
A11: Coverage window | B11: =Input!$B$34
A12: Spares strategy | B12: =Input!$B$35
A14: DEPLOYMENT (one-off)
A15: Survey days | B15: =Model!$B$22
A16: Install days | B16: =Model!$B$23
A17: Design days | B17: =Model!$B$24
A18: Project management days | B18: =Model!$B$25
A19: Total effort (days) | B19: =Model!$B$26
A20: Hardware | B20: =Model!$B$28
A21: One-off price | B21: =Model!$B$33
A23: RUN — RESOURCE BY LOCATION
A24: Country | B24: Role | C24: FTE | D24: Sizing driver
A25: UK | B25: Field Engineer | C25: =Model!$F$41 | D25: =Model!$G$41
A26: DE | B26: Field Engineer | C26: =Model!$F$42 | D26: =Model!$G$42
A27: FR | B27: Field Engineer | C27: =Model!$F$43 | D27: =Model!$G$43
A28: NL | B28: Field Engineer | C28: =Model!$F$44 | D28: =Model!$G$44
A29: PL | B29: Field Engineer | C29: =Model!$F$45 | D29: =Model!$G$45
A30: PL | B30: NOC Engineer | C30: =Model!$B$50 | D30: central
A31: PL | B31: Service Desk | C31: =Model!$B$51 | D31: central
A32: Lead country | B32: Service Delivery Manager | C32: =Model!$B$57 | D32: contract band
A33: Total run FTE | B33: =Model!$B$67
A35: RUN — ANNUAL COST BUILD
A36: Labour | B36: =Model!$B$58
A37: Travel | B37: =Model!$B$59
A38: Spares | B38: =Model!$B$60
A39: Tooling | B39: =Model!$B$61
A40: Overhead | B40: =Model!$B$62
A41: Contingency | B41: =Model!$B$63
A42: Annual price (year 1) | B42: =Model!$B$65
A43: Monthly price (year 1) | B43: =Model!$B$66
A45: CONTRACT VALUE
...

Sheet Input
A1: GP-20 · SOLUTION & COST ARCHITECT
A2: Managed LAN / WLAN rollout with field-support wrap
A3: ILLUSTRATIVE MODEL — synthetic rates, not NSC pricing. Yellow cells are inputs.
A5: ENGAGEMENT
A6: Client name | B6: Aurelian Global (illustrative)
A7: RFP reference | B7: RFP-2026-114
A8: Contract term (years) | B8: 5
A9: Rollout duration (months) | B9: 9
A11: ESTATE
A12: Sites — Small (≤50 users) | B12: 62
A13: Sites — Medium (51–250) | B13: 28
A14: Sites — Large (251–1000) | B14: 9
A15: Sites — Campus (>1000) | B15: 2
A16: Total sites | B16: =SUM(B12:B15)
A17: Total end users | C17: Leave blank to derive from site bands
A18: Access switch count | C18: Leave blank to derive from user count
A20: COUNTRY MIX (shares of estate)
A21: UK | B21: 0.45
A22: DE | B22: 0.25
A23: FR | B23: 0.15
A24: NL | B24: 0.1
A25: PL | B25: 0.05
A26: Total (auto-normalised if ≠ 100%) | B26: =SUM(B21:B25)
A28: DEPLOYMENT
A29: Survey type | B29: hybrid | C29: predictive / hybrid / onsite
A30: Install window | B30: business_hours | C30: out_of_hours applies a ×1.35 uplift
A32: SERVICE (the field-support wrap)
A33: SLA tier | B33: gold | C33: gold / platinum commit to on-site response
A34: Coverage window | B34: 24x7 | C34: Drives shift-rota headcount
A35: Spares strategy | B35: regional
A36: Monitoring included | B36: TRUE
A37: Service desk included | B37: TRUE
A39: COMMERCIALS
A40: Target margin % | B40: 0.22
A41: Contingency % | B41: 0.05
A42: Annual indexation % | B42: 0.03

Sheet Rates
A1: RATE CARD — ILLUSTRATIVE / SYNTHETIC DATA
A2: Not NSC pricing. Replace this sheet with the real rate card; no formula changes required.
A4: COUNTRY RATES (loaded day rates, GBP)
A5: Country | B5: Field | C5: NOC | D5: Service Desk | E5: SDM | F5: Travel/incident
A6: UK | B6: 540 | C6: 470 | D6: 330 | E6: 720 | F6: 68
A7: DE | B7: 575 | C7: 495 | D7: 355 | E7: 760 | F7: 62
A8: FR | B8: 530 | C8: 460 | D8: 335 | E8: 700 | F8: 58
A9: NL | B9: 560 | C9: 485 | D9: 350 | E9: 740 | F9: 54
A10: PL | B10: 295 | C10: 260 | D10: 185 | E10: 430 | F10: 41
A12: SITE BANDS
A13: Band | B13: APs per site | C13: Users per site
A14: small | B14: 4 | C14: 30
A15: medium | B15: 14 | C15: 140
A16: large | B16: 45 | C16: 550
A17: campus | B17: 140 | C17: 1800
A19: SLA TIERS
A20: Tier | B20: FTE multiplier | C20: On-site response | D20: Triggers floor
A21: bronze | B21: 1 | C21: Next business day | D21: 0
A22: silver | B22: 1.15 | C22: 8 business hours | D22: 0
A23: gold | B23: 1.4 | C23: 4 business hours | D23: 1
A24: platinum | B24: 1.9 | C24: 2 business hours | D24: 1
A26: COVERAGE WINDOWS
A27: Coverage | B27: FTE multiplier | C27: Presence FTE per post
A28: 8x5 | B28: 1 | C28: 1.15
A29: 12x5 | B29: 1.35 | C29: 1.7
A30: 24x7 | B30: 3.2 | C30: 4.8
A32: SPARES STRATEGY
A33: Strategy | B33: % of hardware value
A34: none | B34: 0
A35: central | B35: 0.025
A36: regional | B36: 0.045
A37: onsite | B37: 0.085
A39: SURVEY TYPE
A40: Type | B40: Days per AP
A41: predictive | B41: 0.02
A42: hybrid | B42: 0.035
A43: onsite | B43: 0.055
A45: MODEL CONSTANTS
A46: Constant | B46: Value
A47: AP_INSTALL_DAYS | B47: 0.06
...

Sheet Model
A1: MODEL — live calculation chain
A3: ESTATE DERIVATION
A4: Total APs | B4: =SUMPRODUCT(Input!$B$12:$B$15,Rates!$B$14:$B$17)
A5: Total end users | B5: =IF(Input!$B$17="",SUMPRODUCT(Input!$B$12:$B$15,Rates!$C$14:$C$17),Input!$B$17) | C5: RFP value if given, else derived from bands
A6: Access switches | B6: =IF(Input!$B$18="",MAX(Input!$B$16,CEILING(Model!$B$5*Rates!$B$63/Rates!$B$62,1)),Input!$B$18)
A7: Hardware value | B7: =Model!$B$4*Rates!$B$64+Model!$B$6*Rates!$B$65
A9: RATE LOOKUPS
A10: Survey days per AP | B10: =VLOOKUP(Input!$B$29,Rates!$A$41:$B$43,2,FALSE)
A11: SLA FTE multiplier | B11: =VLOOKUP(Input!$B$33,Rates!$A$21:$D$24,2,FALSE)
A12: SLA on-site response | B12: =VLOOKUP(Input!$B$33,Rates!$A$21:$D$24,3,FALSE)
A13: SLA triggers coverage floor | B13: =VLOOKUP(Input!$B$33,Rates!$A$21:$D$24,4,FALSE)
A14: Coverage FTE multiplier | B14: =VLOOKUP(Input!$B$34,Rates!$A$28:$C$30,2,FALSE)
A15: Presence FTE per post | B15: =VLOOKUP(Input!$B$34,Rates!$A$28:$C$30,3,FALSE)
A16: Spares % of hardware | B16: =VLOOKUP(Input!$B$35,Rates!$A$34:$B$37,2,FALSE)
A17: Blended field day rate | B17: =SUMPRODUCT(Input!$B$21:$B$25,Rates!$B$6:$B$10)/Input!$B$26
A18: Blended SDM day rate | B18: =SUMPRODUCT(Input!$B$21:$B$25,Rates!$E$6:$E$10)/Input!$B$26
A19: Blended travel per incident | B19: =SUMPRODUCT(Input!$B$21:$B$25,Rates!$F$6:$F$10)/Input!$B$26
A21: DEPLOYMENT (one-off)
A22: Survey days | B22: =Model!$B$4*Model!$B$10
A23: Install days | B23: =(Model!$B$4*Rates!$B$47+Model!$B$6*Rates!$B$48+Input!$B$16*Rates!$B$49)*IF(Input!$B$30="out_of_hours",Rates!$B$53,1)
A24: Design days | B24: =Rates!$B$50+Input!$B$16*Rates!$B$51
A25: Project management days | B25: =(Model!$B$22+Model!$B$23+Model!$B$24)*Rates!$B$52
A26: Total deployment days | B26: =Model!$B$22+Model!$B$23+Model!$B$24+Model!$B$25
A27: Deployment labour | B27: =(Model!$B$22+Model!$B$23)*Model!$B$17+(Model!$B$24+Model!$B$25)*Model!$B$18
A28: Deployment hardware | B28: =Model!$B$7
A29: Deployment tooling | B29: =Input!$B$16*Rates!$B$66
A30: Deployment overhead | B30: =Model!$B$27*Rates!$B$67
A31: Deployment contingency | B31: =(Model!$B$27+Model!$B$28+Model!$B$29+Model!$B$30)*Input!$B$41
A32: Deployment cost | B32: =Model!$B$27+Model!$B$28+Model!$B$29+Model!$B$30+Model!$B$31
A33: Deployment PRICE | B33: =Model!$B$32/(1-Input!$B$40)
A35: RUN — DEMAND
A36: Incidents per annum | B36: =Model!$B$4*Rates!$B$54+Model!$B$6*Rates!$B$55
A37: Demand-driven field FTE (total) | B37: =Model!$B$36*Rates!$B$56/Rates!$B$57*Model!$B$11*Model!$B$14
A39: RUN — FIELD PRESENCE BY COUNTRY (max of demand vs coverage floor)
A40: Country | B40: Share | C40: Demand FTE | D40: Posts | E40: Floor FTE | F40: Applied FTE | G40: Driver | H40: Labour
A41: UK | B41: =(Input!$B$21/Input!$B$26) | C41: =Model!$B$37*$B41 | D41: =IF(OR(Model!$B$13<>1,$B41=0),0,MAX(1,CEILING(Input!$B$16*$B41/Rates!$B$68,1))) | E41: =$D41*Model!$B$15 | F41: =MAX($C41,$E41) | G41: =IF($E41>$C41,"coverage floor","incident volume") | H41: =$F41*INDEX(Rates!$B$6:$B$10,1)*Rates!$B$58
A42: DE | B42: =(Input!$B$22/Input!$B$26) | C42: =Model!$B$37*$B42 | D42: =IF(OR(Model!$B$13<>1,$B42=0),0,MAX(1,CEILING(Input!$B$16*$B42/Rates!$B$68,1))) | E42: =$D42*Model!$B$15 | F42: =MAX($C42,$E42) | G42: =IF($E42>$C42,"coverage floor","incident volume") | H42: =$F42*INDEX(Rates!$B$6:$B$10,2)*Rates!$B$58
A43: FR | B43: =(Input!$B$23/Input!$B$26) | C43: =Model!$B$37*$B43 | D43: =IF(OR(Model!$B$13<>1,$B43=0),0,MAX(1,CEILING(Input!$B$16*$B43/Rates!$B$68,1))) | E43: =$D43*Model!$B$15 | F43: =MAX($C43,$E43) | G43: =IF($E43>$C43,"coverage floor","incident volume") | H43: =$F43*INDEX(Rates!$B$6:$B$10,3)*Rates!$B$58
A44: NL | B44: =(Input!$B$24/Input!$B$26) | C44: =Model!$B$37*$B44 | D44: =IF(OR(Model!$B$13<>1,$B44=0),0,MAX(1,CEILING(Input!$B$16*$B44/Rates!$B$68,1))) | E44: =$D44*Model!$B$15 | F44: =MAX($C44,$E44) | G44: =IF($E44>$C44,"coverage floor","incident volume") | H44: =$F44*INDEX(Rates!$B$6:$B$10,4)*Rates!$B$58
A45: PL | B45: =(Input!$B$25/Input!$B$26) | C45: =Model!$B$37*$B45 | D45: =IF(OR(Model!$B$13<>1,$B45=0),0,MAX(1,CEILING(Input!$B$16*$B45/Rates!$B$68,1))) | E45: =$D45*Model!$B$15 | F45: =MAX($C45,$E45) | G45: =IF($E45>$C45,"coverage floor","incident volume") | H45: =$F45*INDEX(Rates!$B$6:$B$10,5)*Rates!$B$58
...
